Workbook

Sheet Portfolio Insights
A1: Model Portfolio Insights
A2: Analysis of strategic asset allocation, fee, CPI+ target and annualised volatility across the six model portfolios.
A4: Portfolios | D4: Avg TER | G4: Target Range | J4: Volatility Range
A5: =COUNTA('Model Portfolios'!B8:B13) -> 6 | D5: =AVERAGE('Model Portfolios'!Q8:Q13) -> 0.005 | G5: =MAX('Model Portfolios'!R8:R13)-MIN('Model Portfolios'!R8:R13) -> 0.06 | J5: =MAX('Model Portfolios'!S8:S13)-MIN('Model Portfolios'!S8:S13) -> 0.1051
A6: model portfolios | D6: fee p.a. | G6: CPI+ spread | J6: annualised std dev (7yr)
A8: STORY IN BRIEF
A9: The worksheet covers six model portfolios across five risk categories, from the income-heavy DNA Income (Conservative) to two equity-heavy Aggressive variants. Growth assets rise from 3% to 99% along the ladder while income assets fall from 97% to 1%. The two Aggressive models differ by geography: DNA Aggressive Equity is ~96% equity split evenly SA/global, while DNA Global Aggressive is ~85% equity but almost entirely global. TERs range 0.37%-0.69% (avg 0.50%) and are not perfectly aligned with risk - the lowest-fee model is the SA-equity Aggressive. Volatility (7-year basis) rises from 2.1% to 12.6%, peaking at the fully-global Aggressive model. Every model totals 100%.
A13: Risk Category | B13: Model Name | C13: Growth Assets | D13: Income Assets | E13: Local Assets | F13: Global Assets | G13: SA Equity | H13: Global Equity | I13: SA Bonds | J13: Global Bonds | K13: Property | L13: Cash | M13: TER | N13: Volatility (7yr)
A14: ='Model Portfolios'!B8 -> Conservative | B14: ='Model Portfolios'!C8 -> DNA Income Portfolio | C14: =SUM('Model Portfolios'!D8:E8,'Model Portfolios'!H8:I8) -> 0.03 | D14: =SUM('Model Portfolios'!F8:G8,'Model Portfolios'!J8:K8) -> 0.97 | E14: =SUM('Model Portfolios'!D8,'Model Portfolios'!F8,'Model Portfolios'!H8,'Model Portfolios'!J8) -> 0.9 | F14: =SUM('Model Portfolios'!E8,'Model Portfolios'!G8,'Model Portfolios'!I8,'Model Portfolios'!K8) -> 0.1 | G14: ='Model Portfolios'!D8 -> 0 | H14: ='Model Portfolios'!E8 -> 0 | I14: ='Model Portfolios'!F8 -> 0.57 | J14: ='Model Portfolios'!G8 -> 0.085 | K14: =SUM('Model Portfolios'!H8:I8) -> 0.03 | L14: =SUM('Model Portfolios'!J8:K8) -> 0.315 | M14: ='Model Portfolios'!Q8 -> 0.0045 | N14: ='Model Portfolios'!S8 -> 0.0211
A15: ='Model Portfolios'!B9 -> Moderate Conservative | B15: ='Model Portfolios'!C9 -> DNA Moderate Conservative Portfolio | C15: =SUM('Model Portfolios'!D9:E9,'Model Portfolios'!H9:I9) -> 0.425 | D15: =SUM('Model Portfolios'!F9:G9,'Model Portfolios'!J9:K9) -> 0.575 | E15: =SUM('Model Portfolios'!D9,'Model Portfolios'!F9,'Model Portfolios'!H9,'Model Portfolios'!J9) -> 0.775 | F15: =SUM('Model Portfolios'!E9,'Model Portfolios'!G9,'Model Portfolios'!I9,'Model Portfolios'!K9) -> 0.225 | G15: ='Model Portfolios'!D9 -> 0.25 | H15: ='Model Portfolios'!E9 -> 0.14 | I15: ='Model Portfolios'!F9 -> 0.39 | J15: ='Model Portfolios'!G9 -> 0.085 | K15: =SUM('Model Portfolios'!H9:I9) -> 0.035 | L15: =SUM('Model Portfolios'!J9:K9) -> 0.1 | M15: ='Model Portfolios'!Q9 -> 0.0066 | N15: ='Model Portfolios'!S9 -> 0.0767
A16: ='Model Portfolios'!B10 -> Moderate | B16: ='Model Portfolios'!C10 -> DNA Moderate Portfolio | C16: =SUM('Model Portfolios'!D10:E10,'Model Portfolios'!H10:I10) -> 0.6 | D16: =SUM('Model Portfolios'!F10:G10,'Model Portfolios'!J10:K10) -> 0.4 | E16: =SUM('Model Portfolios'!D10,'Model Portfolios'!F10,'Model Portfolios'!H10,'Model Portfolios'!J10) -> 0.69 | F16: =SUM('Model Portfolios'!E10,'Model Portfolios'!G10,'Model Portfolios'!I10,'Model Portfolios'!K10) -> 0.31 | G16: ='Model Portfolios'!D10 -> 0.31 | H16: ='Model Portfolios'!E10 -> 0.255 | I16: ='Model Portfolios'!F10 -> 0.25 | J16: ='Model Portfolios'!G10 -> 0.055 | K16: =SUM('Model Portfolios'!H10:I10) -> 0.035 | L16: =SUM('Model Portfolios'!J10:K10) -> 0.095 | M16: ='Model Portfolios'!Q10 -> 0.004 | N16: ='Model Portfolios'!S10 -> 0.0944
A17: ='Model Portfolios'!B11 -> Moderate Aggressive | B17: ='Model Portfolios'!C11 -> DNA Moderate Aggressive Portfolio | C17: =SUM('Model Portfolios'!D11:E11,'Model Portfolios'!H11:I11) -> 0.74 | D17: =SUM('Model Portfolios'!F11:G11,'Model Portfolios'!J11:K11) -> 0.26 | E17: =SUM('Model Portfolios'!D11,'Model Portfolios'!F11,'Model Portfolios'!H11,'Model Portfolios'!J11) -> 0.655 | F17: =SUM('Model Portfolios'!E11,'Model Portfolios'!G11,'Model Portfolios'!I11,'Model Portfolios'!K11) -> 0.345 | G17: ='Model Portfolios'!D11 -> 0.43 | H17: ='Model Portfolios'!E11 -> 0.28 | I17: ='Model Portfolios'!F11 -> 0.165 | J17: ='Model Portfolios'!G11 -> 0.065 | K17: =SUM('Model Portfolios'!H11:I11) -> 0.03 | L17: =SUM('Model Portfolios'!J11:K11) -> 0.03 | M17: ='Model Portfolios'!Q11 -> 0.0069 | N17: ='Model Portfolios'!S11 -> 0.1041
A18: ='Model Portfolios'!B12 -> Aggressive | B18: ='Model Portfolios'!C12 -> DNA Agressive Equity Portfolio | C18: =SUM('Model Portfolios'!D12:E12,'Model Portfolios'!H12:I12) -> 0.99 | D18: =SUM('Model Portfolios'!F12:G12,'Model Portfolios'!J12:K12) -> 0.01 | E18: =SUM('Model Portfolios'!D12,'Model Portfolios'!F12,'Model Portfolios'!H12,'Model Portfolios'!J12) -> 0.51 | F18: =SUM('Model Portfolios'!E12,'Model Portfolios'!G12,'Model Portfolios'!I12,'Model Portfolios'!K12) -> 0.49 | G18: ='Model Portfolios'!D12 -> 0.475 | H18: ='Model Portfolios'!E12 -> 0.49 | I18: ='Model Portfolios'!F12 -> 0 | J18: ='Model Portfolios'!G12 -> 0 | K18: =SUM('Model Portfolios'!H12:I12) -> 0.025 | L18: =SUM('Model Portfolios'!J12:K12) -> 0.01 | M18: ='Model Portfolios'!Q12 -> 0.0037 | N18: ='Model Portfolios'!S12 -> 0.1184
A19: ='Model Portfolios'!B13 -> Aggressive | B19: ='Model Portfolios'!C13 -> DNA Global Aggressive Portfolio | C19: =SUM('Model Portfolios'!D13:E13,'Model Portfolios'!H13:I13) -> 0.865 | D19: =SUM('Model Portfolios'!F13:G13,'Model Portfolios'!J13:K13) -> 0.135 | E19: =SUM('Model Portfolios'!D13,'Model Portfolios'!F13,'Model Portfolios'!H13,'Model Portfolios'!J13) -> 0.055 | F19: =SUM('Model Portfolios'!E13,'Model Portfolios'!G13,'Model Portfolios'!I13,'Model Portfolios'!K13) -> 0.945 | G19: ='Model Portfolios'!D13 -> 0.005 | H19: ='Model Portfolios'!E13 -> 0.84 | I19: ='Model Portfolios'!F13 -> 0 | J19: ='Model Portfolios'!G13 -> 0.105 | K19: =SUM('Model Portfolios'!H13:I13) -> 0.02 | L19: =SUM('Model Portfolios'!J13:K13) -> 0.03 | M19: ='Model Portfolios'!Q13 -> 0.0043 | N19: ='Model Portfolios'!S13 -> 0.1262
A22: Risk Category | B22: Growth Assets | C22: Income Assets | D22: Volatility | F22: Risk Category | G22: TER | H22: Volatility | J22: Asset Class | K22: Average Allocation
A23: =A14 -> Conservative | B23: =C14 -> 0.03 | C23: =D14 -> 0.97 | D23: =N14 -> 0.0211 | F23: =A14 -> Conservative | G23: =M14 -> 0.0045 | H23: =N14 -> 0.0211 | J23: SA Equity | K23: =AVERAGE(G14:G19) -> 0.245
A24: =A15 -> Moderate Conservative | B24: =C15 -> 0.425 | C24: =D15 -> 0.575 | D24: =N15 -> 0.0767 | F24: =A15 -> Moderate Conservative | G24: =M15 -> 0.0066 | H24: =N15 -> 0.0767 | J24: Global Equity | K24: =AVERAGE(H14:H19) -> 0.33416667
A25: =A16 -> Moderate | B25: =C16 -> 0.6 | C25: =D16 -> 0.4 | D25: =N16 -> 0.0944 | F25: =A16 -> Moderate | G25: =M16 -> 0.004 | H25: =N16 -> 0.0944 | J25: SA Bonds | K25: =AVERAGE(I14:I19) -> 0.22916667
A26: =A17 -> Moderate Aggressive | B26: =C17 -> 0.74 | C26: =D17 -> 0.26 | D26: =N17 -> 0.1041 | F26: =A17 -> Moderate Aggressive | G26: =M17 -> 0.0069 | H26: =N17 -> 0.1041 | J26: Global Bonds | K26: =AVERAGE(J14:J19) -> 0.065833333
A27: =A18 -> Aggressive | B27: =C18 -> 0.99 | C27: =D18 -> 0.01 | D27: =N18 -> 0.1184 | F27: =A18 -> Aggressive | G27: =M18 -> 0.0037 | H27: =N18 -> 0.1184 | J27: Property | K27: =AVERAGE(K14:K19) -> 0.029166667
A28: =A19 -> Aggressive | B28: =C19 -> 0.865 | C28: =D19 -> 0.135 | D28: =N19 -> 0.1262 | F28: =A19 -> Aggressive | G28: =M19 -> 0.0043 | H28: =N19 -> 0.1262 | J28: Cash | K28: =AVERAGE(L14:L19) -> 0.096666667
H50: KEY FINDINGS
H51: 1 | I51: Risk ladder is coherent | J51: Growth assets climb from 3.0% (DNA Income) to 99.0% (DNA Aggressive Equity), while income assets fall from 97.0% to 1.0%.
H52: 2 | I52: Two aggressive variants differ by geography | J52: DNA Aggressive Equity is ~96% equity split evenly SA/global; DNA Global Aggressive is ~85% equity but almost entirely global (84% global equity).
H53: 3 | I53: Fees are not aligned with risk | J53: Lowest TER is DNA Aggressive Equity at 0.37%; highest is DNA Moderate Aggressive at 0.69%. Average across the six models is 0.50%.
H54: 4 | I54: Volatility peaks at the global model | J54: Annualised volatility (7-year basis) rises from 2.1% (Income) to 12.6% (Global Aggressive) - the fully-global model, higher than the SA-equity Aggressive at 11.8%.
H55: 5 | I55: Allocations are internally consistent | J55: All six portfolios sum to exactly 100.0% in the source allocation check column.

Sheet Model Portfolios
B2: Model Portfolio Metrics
B3: Risk-profiled model portfolios: strategic asset allocation, fees, return target and volatility
B5: Legend: | C5: Blue text = hardcoded input (edit as needed) | E5: Black text = formula (do not overwrite) | G5: Yellow fill = check / fill-in cell
B7: Risk Category | C7: Model Name | D7: SA Equity | E7: Global Equity | F7: SA Bonds | G7: Global Bonds | H7: SA Property | I7: Global Property | J7: SA Cash | K7: Global Cash | L7: SA Assets | M7: Global Assets | N7: Growth Assets | O7: Conservative Assets | P7: Total Allocation | Q7: Fee (TER, % p.a.) | R7: CPI+ Return Target | S7: Volatility (Annualised Std Dev) | T7: Vol period
B8: Conservative | C8: DNA Income Portfolio | D8: 0 | E8: 0 | F8: 0.57 | G8: 0.085 | H8: 0.03 | I8: 0 | J8: 0.3 | K8: 0.015 | L8: =SUM(D8,F8,H8,J8) -> 0.9 | M8: =SUM(E8,G8,I8,K8) -> 0.1 | N8: =SUM(D8:E8,H8:I8) -> 0.03 | O8: =SUM(F8:G8,J8:K8) -> 0.97 | P8: =SUM(D8:K8) -> 1 | Q8: 0.0045 | R8: 0.01 | S8: 0.0211 | T8: 7yr
B9: Moderate Conservative | C9: DNA Moderate Conservative Portfolio | D9: 0.25 | E9: 0.14 | F9: 0.39 | G9: 0.085 | H9: 0.035 | I9: 0 | J9: 0.1 | K9: 0 | L9: =SUM(D9,F9,H9,J9) -> 0.775 | M9: =SUM(E9,G9,I9,K9) -> 0.225 | N9: =SUM(D9:E9,H9:I9) -> 0.425 | O9: =SUM(F9:G9,J9:K9) -> 0.575 | P9: =SUM(D9:K9) -> 1 | Q9: 0.0066 | R9: 0.025 | S9: 0.0767 | T9: 7yr
B10: Moderate | C10: DNA Moderate Portfolio | D10: 0.31 | E10: 0.255 | F10: 0.25 | G10: 0.055 | H10: 0.035 | I10: 0 | J10: 0.095 | K10: 0 | L10: =SUM(D10,F10,H10,J10) -> 0.69 | M10: =SUM(E10,G10,I10,K10) -> 0.31 | N10: =SUM(D10:E10,H10:I10) -> 0.6 | O10: =SUM(F10:G10,J10:K10) -> 0.4 | P10: =SUM(D10:K10) -> 1 | Q10: 0.004 | R10: 0.035 | S10: 0.0944 | T10: 7yr
B11: Moderate Aggressive | C11: DNA Moderate Aggressive Portfolio | D11: 0.43 | E11: 0.28 | F11: 0.165 | G11: 0.065 | H11: 0.03 | I11: 0 | J11: 0.03 | K11: 0 | L11: =SUM(D11,F11,H11,J11) -> 0.655 | M11: =SUM(E11,G11,I11,K11) -> 0.345 | N11: =SUM(D11:E11,H11:I11) -> 0.74 | O11: =SUM(F11:G11,J11:K11) -> 0.26 | P11: =SUM(D11:K11) -> 1 | Q11: 0.0069 | R11: 0.05 | S11: 0.1041 | T11: 7yr
B12: Aggressive | C12: DNA Agressive Equity Portfolio | D12: 0.475 | E12: 0.49 | F12: 0 | G12: 0 | H12: 0.025 | I12: 0 | J12: 0.01 | K12: 0 | L12: =SUM(D12,F12,H12,J12) -> 0.51 | M12: =SUM(E12,G12,I12,K12) -> 0.49 | N12: =SUM(D12:E12,H12:I12) -> 0.99 | O12: =SUM(F12:G12,J12:K12) -> 0.01 | P12: =SUM(D12:K12) -> 1 | Q12: 0.0037 | R12: 0.065 | S12: 0.1184 | T12: 7yr
B13: Aggressive | C13: DNA Global Aggressive Portfolio | D13: 0.005 | E13: 0.84 | F13: 0 | G13: 0.105 | H13: 0.02 | I13: 0 | J13: 0.03 | K13: 0 | L13: =SUM(D13,F13,H13,J13) -> 0.055 | M13: =SUM(E13,G13,I13,K13) -> 0.945 | N13: =SUM(D13:E13,H13:I13) -> 0.865 | O13: =SUM(F13:G13,J13:K13) -> 0.135 | P13: =SUM(D13:K13) -> 1 | Q13: 0.0043 | R13: 0.07 | S13: 0.1262 | T13: 7yr
B14: Allocation check: Total Allocation in column P should equal 100.0% for every model.
B16: Notes:
B17: - All figures below are illustrative placeholders provided as a starting template — replace blue/yellow cells with your actual model portfolio data.
B18: - Model Name (yellow fill): enter the actual fund/model name for each risk category.
B19: - Asset allocation: strategic (long-term) weights per model; each row should sum to 100% (see conditional check in column L).
B20: - Fee (TER): total expense ratio, % per annum, illustrative only.
B21: - CPI+ Return Target: long-term real return objective above South African CPI inflation, illustrative only.
B22: - Volatility: 7-year annualised standard deviation of the blended model (source: DNA fund-blend vol working, 17 Jul 2026). Period noted in the 'Vol period' column.

Sheet Underlying Funds
A1: DNA Model Portfolios - Underlying Fund Factsheet Data
A2: Metrics extracted from fund MDDs/fact sheets in \Blended Portfolio metrics\ folders. Rebuilt 2026-07-22. Dates: M&G/Coronation/Prescient = 30 Jun 2026; Nedgroup/Satrix = 31 May 2026.
A4: TABLE 1 - Fund metrics (per fact sheet)
A5: Fund | B5: Class | C5: As-at | D5: ASISA Category | E5: TER | F5: TIC | G5: Volatility (ann.) | H5: 1yr | I5: 3yr | J5: 5yr | K5: Source PDF
A6: Coronation Strategic Income | B6: A | C6: 30 Jun 2026 | D6: SA Multi-Asset - Income | E6: 0.0087 | F6: 0.0087 | G6: 0.027 | H6: 0.098 | I6: 0.11 | J6: 0.089 | K6: 2026-June-Strategic-Income-Comprehensive_CSIF.pdf
A7: Nedgroup Core Income | B7: C | C7: 31 May 2026 | D7: SA Interest Bearing - Short Term | E7: 0.003 | F7: 0.003 | H7: 0.081 | I7: 0.071 | J7: 0.079 | K7: Nedgroup Investments Core Income Fund C.pdf
A8: M&G Inflation Plus | B8: A | C8: 30 Jun 2026 | D8: SA Multi-Asset - Low Equity | E8: 0.0135 | F8: 0.0141 | G8: 0.067 | H8: 0.135 | I8: 0.124 | J8: 0.111 | K8: mandg-inflation-plus-fund June26.pdf
A9: Nedgroup Core Guarded | B9: B | C9: 31 May 2026 | D9: SA Multi-Asset - Low Equity | E9: 0.0045 | F9: 0.0047 | G9: 0.053 | H9: 0.159 | I9: 0.127 | J9: 0.109 | K9: Nedgroup Investments Core Guarded Fund B.pdf
A10: M&G Balanced | B10: A | C10: 30 Jun 2026 | D10: SA Multi-Asset - High Equity | E10: 0.0141 | F10: 0.015 | G10: 0.106 | H10: 0.115 | I10: 0.125 | J10: 0.12 | K10: mandg-balanced-fund JUne26.pdf
A11: Nedgroup Core Diversified | B11: B | C11: 31 May 2026 | D11: SA Multi-Asset - High Equity | E11: 0.0045 | F11: 0.0047 | G11: 0.08 | H11: 0.187 | I11: 0.15 | J11: 0.129 | K11: Nedgroup Investments Core Diversified Fund B June26.pdf
A12: Prescient Core Equity | B12: A2 | C12: 30 Jun 2026 | D12: SA Equity - General | E12: 0.0037 | F12: 0.0038 | G12: 0.1504 | H12: 0.1995 | I12: 0.1977 | J12: 0.1486 | K12: prescient-core-equity-fund-a2-june-2026-pceqtfa2.pdf
A13: Satrix MSCI World | B13: A1 | C13: 31 May 2026 | D13: Global Equity - General | E13: 0.0069 | F13: 0.0072 | H13: 0.1355 | I13: 0.1314 | J13: 0.1487 | K13: Satrix MSCI World Index Fund 31 May 2026 Class A1.pdf
A14: Nedgroup Core Global Feeder Fund | B14: A | C14: 30 Jun 2026 | D14: Global Multi-Asset - High Equity | E14: 0.0051 | F14: 0.0051 | G14: 0.114 | H14: 0.071 | I14: 0.092 | J14: 0.1 | K14: Nedgroup Investments Core Global Feeder Fund A.pdf
A16: TABLE 2 - Asset allocation mapped to the 8 model asset classes (% of fund)
A17: Mapping: SA/Global ILBs & credit-linked notes -> Bonds; Cash & Money Market/NCDs -> Cash; listed property -> Property. Coronation look-through; Core Income = 100% SA Cash; Prescient = SA equity tracker; Satrix = global equity tracker.
A18: Fund | B18: SA Equity | C18: Global Equity | D18: SA Bonds | E18: Global Bonds | F18: SA Property | G18: Global Property | H18: SA Cash | I18: Global Cash | J18: Total
A19: Coronation Strategic Income | B19: 0 | C19: 0 | D19: 0.64 | E19: 0.12 | F19: 0.045 | G19: 0.002 | H19: 0.192 | I19: 0.001 | J19: =SUM(B19:I19) -> 1
A20: Nedgroup Core Income | B20: 0 | C20: 0 | D20: 0 | E20: 0 | F20: 0 | G20: 0 | H20: 1 | I20: 0 | J20: =SUM(B20:I20) -> 1
A21: M&G Inflation Plus | B21: 0.257 | C21: 0.098 | D21: 0.43 | E21: 0.109 | F21: 0.041 | G21: 0 | H21: 0.065 | I21: 0 | J21: =SUM(B21:I21) -> 1
A22: Nedgroup Core Guarded | B22: 0.223 | C22: 0.155 | D22: 0.263 | E22: 0.045 | F22: 0.029 | G22: 0.03 | H22: 0.236 | I22: 0.019 | J22: =SUM(B22:I22) -> 1
A23: M&G Balanced | B23: 0.441 | C23: 0.242 | D23: 0.151 | E23: 0.073 | F23: 0.026 | G23: 0.002 | H23: 0.048 | I23: 0.017 | J23: =SUM(B23:I23) -> 1
A24: Nedgroup Core Diversified | B24: 0.395 | C24: 0.31 | D24: 0.122 | E24: 0.063 | F24: 0.024 | G24: 0.016 | H24: 0.053 | I24: 0.017 | J24: =SUM(B24:I24) -> 1
A25: Prescient Core Equity | B25: 0.943 | C25: 0 | D25: 0 | E25: 0 | F25: 0.05 | G25: 0 | H25: 0.007 | I25: 0 | J25: =SUM(B25:I25) -> 1
A26: Satrix MSCI World | B26: 0 | C26: 0.9965 | D26: 0 | E26: 0 | F26: 0 | G26: 0 | H26: 0 | I26: 0.0035 | J26: =SUM(B26:I26) -> 1
A27: Nedgroup Core Global Feeder Fund | B27: 0 | C27: 0.72 | D27: 0 | E27: 0.197 | F27: 0 | G27: 0.035 | H27: 0.001 | I27: 0.047 | J27: =SUM(B27:I27) -> 1
A29: TABLE 3 - Top holdings (per fact sheet)
A30: Fund | B30: Top 5 holdings / credit exposures
A31: Coronation Strategic Income | B31: RSA 45.1%, Standard Bank 21.2%, Firstrand 9.9%, Nedbank 7.2%, ABSA 7.1% (top credit exposure)
A32: Nedgroup Core Income | B32: Nedbank 24.8%, Standard Bank 17.4%, ABSA 17.2%, Firstrand 16.4%, BNP Paribas 9.5%
A33: M&G Inflation Plus | B33: RSA R2044 4.4%, R2040 4.3%, R2035 3.8%, ILB I2046 3.8%, R2037 3.7%
A34: Nedgroup Core Guarded | B34: RSA R2044 2.9%, R2032 2.6%, R2035 2.5%, R2040 2.1%, R2037 2.0%
A35: M&G Balanced | B35: Naspers/Prosus 5.9%, MTN 3.2%, Standard Bank 3.1%, AngloGold 3.0%, Gold Fields 2.8%
A36: Nedgroup Core Diversified | B36: Naspers 3.1%, Gold Fields 2.7%, AngloGold 2.5%, Firstrand 2.3%, Standard Bank 2.0%
A37: Prescient Core Equity | B37: Naspers 7.5%, Firstrand 6.1%, Gold Fields 6.1%, AngloGold 5.4%, Capitec 5.3%
A38: Satrix MSCI World | B38: Nvidia 5.2%, Apple 4.9%, Microsoft 3.4%, Amazon 2.8%, Alphabet 2.3%
A39: Nedgroup Core Global Feeder Fund | B39: Nvidia 3.4%, Apple 3.1%, Microsoft 1.9%, Amazon 1.7%, Alphabet 1.4% (global equity via BlackRock)
A41: TABLE 4 - Model blend weights (blue = entered; yellow = to do)
A42: Model | B42: Underlying Fund | C42: Weight | D42: Class | E42: Fee-class TER | F42: Wt check
A43: DNA Income | B43: Coronation Strategic Income | C43: 0.7
B44: Nedgroup Core Income | C44: 0.3 | F44: =C43+C44 -> 1
...

Sheet Monarch Model Portfolios
A1: Monarch Integrate Model Portfolios
A2: Second model-portfolio range, parallel to the DNA range. Source: Monarch Integrate fact sheets (Cogence/Discovery, Morningstar Direct) + underlying-fund MDDs, all dated 30 Jun 2026. Compiled 2026-07-23.
A4: Legend: | B4: Blue text = disclosed input | D4: Orange text = estimated (not disclosed by Monarch)
A6: Risk Category | B6: Model Name | C6: SA Equity | D6: Global Equity | E6: SA Bonds | F6: Global Bonds | G6: SA Property | H6: Global Property | I6: SA Cash | J6: Global Cash | K6: Alternatives | L6: Total Allocation | M6: DFM Fee | N6: Underlying Blended TIC | O6: Total Effective Cost | P6: CPI+ Return Target | Q6: Volatility (5yr, actual) | R6: Reg 28
A7: Conservative | B7: Monarch Integrate Income Portfolio | C7: 0 | D7: 0 | E7: 0.798 | F7: 0.021 | G7: 0.013 | H7: 0 | I7: 0.137 | J7: 0.028 | K7: 0.002 | L7: =SUM(C7:K7) -> 0.999 | M7: 0.003 | N7: 0.0118 | O7: 0.0148 | P7: 0.01 | Q7: 0.0391 | R7: Yes
A8: Moderately Conservative | B8: Monarch Integrate Moderate Conservative Portfolio | C8: 0.104 | D8: 0.231 | E8: 0.552 | F8: 0.055 | G8: 0.012 | H8: 0.001 | I8: 0.011 | J8: 0.026 | K8: 0.008 | L8: =SUM(C8:K8) -> 1 | M8: 0 | N8: 0.013 | O8: 0.018 | P8: 0.025 | Q8: 0.0763 | R8: Yes
A9: Moderate | B9: Monarch Integrate Moderate Portfolio | C9: 0.246 | D9: 0.281 | E9: 0.339 | F9: 0.065 | G9: 0.017 | H9: 0.002 | I9: 0.015 | J9: 0.026 | K9: 0.009 | L9: =SUM(C9:K9) -> 1 | M9: 0 | N9: 0.014 | O9: 0.0196 | P9: 0.035 | Q9: 0.0866 | R9: Yes
A10: Moderately Aggressive | B10: Monarch Integrate Moderate Aggressive Portfolio | C10: 0.373 | D10: 0.299 | E10: 0.185 | F10: 0.067 | G10: 0.022 | H10: 0.003 | I10: 0.017 | J10: 0.025 | K10: 0.009 | L10: =SUM(C10:K10) -> 1 | M10: 0 | N10: 0.0147 | O10: 0.0215 | P10: 0.05 | Q10: 0.0959 | R10: Yes
A11: Aggressive | B11: Monarch Integrate Equity Portfolio | C11: 0.513 | D11: 0.414 | E11: 0 | F11: 0 | G11: 0.015 | H11: 0 | I11: 0.029 | J11: 0.022 | K11: 0.006 | L11: =SUM(C11:K11) -> 0.999 | M11: 0.003 | N11: 0.0219 | O11: 0.0249 | P11: 0.065 | Q11: 0.1063 | R11: No
A13: Allocation check: Total Allocation in column L should equal 100.0% for every model. Total Effective Cost (col O) = DFM Fee (col M) + Underlying Blended TIC (col N) for Income and Equity. For Mod Con / Moderate / Mod Aggressive, Total Effective Cost = the TIC of the actual Cogence Discovery Dynamic Asset Optimiser Fund of Funds each model replicates (Cautious/Moderate/Balanced respectively) - confirmed via each fund's own MDD, see note 7. NOT the DFM+TIC blend of the individual building-block funds (which computed to 1.30%/1.40%/1.47%).
A15: Return target basis (STANDARDIZED 2026-07-24):
A16: CPI+ Return Target is now driven by RISK CATEGORY, not by each range's own funds - the DNA range's CPI+ targets are the house standard and are mirrored onto the matching Monarch risk category, so a DNA model and a Monarch model in the same risk category always show the same return target and (at a given inflation assumption) the same nominal expected return in the simulator.
A17: Mapping: Conservative 1.0% | Moderately Conservative 2.5% | Moderate 3.5% | Moderately Aggressive 5.0% | Aggressive 6.5% (= DNA Aggressive Equity; DNA's other Aggressive model, Global Aggressive, targets 7.0% but Monarch has only one Aggressive model so Aggressive Equity was used - see chat decision 2026-07-24). This SUPERSEDES the fund-of-funds' own stated CPI+ bands (Mod Con 1-3%, Moderate 3-5%, Mod Aggressive 5-7%) and the earlier extrapolated Income/Equity figures used before 2026-07-24.
A19: TIC methodology: Underlying Blended TIC = each underlying fund's own Total Investment Charge (TIC = TER + transaction costs, from its MDD, see Holdings table below) weighted by its portfolio holding %. DFM Fee is Cogence's separate overlay fee (0.30% for Income/Equity; 0% for the other three - "no additional discretionary fund management fee charged"). Total Effective Cost = DFM Fee + Underlying Blended TIC. Small ZAR/USD cash slivers assumed 0% fee. FLAG: Cogence Global Growth (USD) fact sheet discloses only TER (1.43%), no TC/TIC line - its TER was used as a TIC proxy (affects Mod Con/Moderate/Mod Aggressive, where it is a 30-37% holding).
A21: Portfolio holdings, with underlying-fund TIC and volatility (from each fund's own MDD, 30 Jun 2026)
A22: Model | B22: Underlying Fund | C22: Weight | D22: Fund TIC | E22: Fund Vol (3yr unless noted)
A23: Income | B23: Discovery Diversified Income (A1) | C23: 0.8 | D23: 0.0118 | E23: 0.0187
A24: Income | B24: Discovery Strategic Bond (A) | C24: 0.2 | D24: 0.0116 | E24: 0.0763
A25: Mod Con | B25: Discovery Strategic Bond (A) | C25: 0.471 | D25: 0.0116 | E25: 0.0763
A26: Mod Con | B26: Cogence Global Growth (USD)* | C26: 0.305 | D26: 0.0143 | E26: 0.1279
A27: Mod Con | B27: Discovery Diversified Income (A1) | C27: 0.088 | D27: 0.0118 | E27: 0.0187
A28: Mod Con | B28: Ninety One SA Equity (G) | C28: 0.072 | D28: 0.0215 | E28: 0.226
A29: Mod Con | B29: Ninety One Active Quants (H) | C29: 0.048 | D29: 0.01 | E29: 0.22
A30: Mod Con | B30: ZAR Cash | C30: 0.008 | D30: 0
A31: Mod Con | B31: Discovery Flexible Property (A) | C31: 0.005 | D31: 0.0152 | E31: 0.1447
A32: Mod Con | B32: USD Cash | C32: 0.003 | D32: 0
A33: Moderate | B33: Cogence Global Growth (USD)* | C33: 0.358 | D33: 0.0143 | E33: 0.1279
A34: Moderate | B34: Discovery Strategic Bond (A) | C34: 0.303 | D34: 0.0116 | E34: 0.0763
A35: Moderate | B35: Ninety One SA Equity (G) | C35: 0.17 | D35: 0.0215 | E35: 0.226
A36: Moderate | B36: Ninety One Active Quants (H) | C36: 0.115 | D36: 0.01 | E36: 0.22
A37: Moderate | B37: Discovery Diversified Income (A1) | C37: 0.039 | D37: 0.0118 | E37: 0.0187
A38: Moderate | B38: ZAR Cash | C38: 0.008 | D38: 0
A39: Moderate | B39: Discovery Flexible Property (A) | C39: 0.005 | D39: 0.0152 | E39: 0.1447
A40: Moderate | B40: USD Cash | C40: 0.002 | D40: 0
A41: Mod Aggressive | B41: Cogence Global Growth (USD)* | C41: 0.369 | D41: 0.0143 | E41: 0.1279
A42: Mod Aggressive | B42: Ninety One SA Equity (G) | C42: 0.255 | D42: 0.0215 | E42: 0.226
A43: Mod Aggressive | B43: Discovery Strategic Bond (A) | C43: 0.177 | D43: 0.0116 | E43: 0.0763
A44: Mod Aggressive | B44: Ninety One Active Quants (H) | C44: 0.176 | D44: 0.01 | E44: 0.22
A45: Mod Aggressive | B45: Discovery Diversified Income (A1) | C45: 0.008 | D45: 0.0118 | E45: 0.0187
A46: Mod Aggressive | B46: ZAR Cash | C46: 0.007 | D46: 0
...
